{"name": "test_demo2", "status": "failed", "statusDetails": {"message": "AssertionError: assert 4 == 5\n +  where 4 = inc(2)", "trace": "self = <测试.test_pytest.Testadd object at 0x7f4b58d91e48>\n\n    @pytest.mark.failed\n    def test_demo2(self):\n>       assert inc(2) == 5\nE       assert 4 == 5\nE        +  where 4 = inc(2)\n\ntest_pytest.py:17: AssertionError"}, "attachments": [{"name": "stdout", "source": "3bc0b572-e96b-439b-bde2-e233f3e02697-attachment.txt", "type": "text/plain"}], "start": 1617091707592, "stop": 1617091707593, "uuid": "dd21339a-edf8-4ef6-88ef-73e341b369b7", "historyId": "1305f81a07d8db2896970847812e4f1a", "testCaseId": "78f3d9e0ebea22668805dfba5942c4a0", "fullName": "test_pytest.Testadd#test_demo2", "labels": [{"name": "tag", "value": "failed"}, {"name": "suite", "value": "test_pytest"}, {"name": "subSuite", "value": "Testadd"}, {"name": "host", "value": "tedu"}, {"name": "thread", "value": "35342-MainThread"}, {"name": "framework", "value": "pytest"}, {"name": "language", "value": "cpython3"}, {"name": "package", "value": "test_pytest"}]}